<robot name="lobot" xmlns:xacro="http://ros.org/wiki/xacro">
    <xacro:include filename="$(find lobot_description)/urdf/materials.urdf.xacro" />
    <xacro:include filename="$(find lobot_description)/gazebo/gazebo_arm.urdf.xacro" />
    <xacro:gazebo_macro robot="arm_standalone" control_update_rate="100" status_update_rate="500" />
    <link name="world" />
    <joint name="world_joint" type="fixed">
        <parent link="world" />
        <child link="arm_1_link" />
        <origin xyz="0 0 0.03" rpy="0 0 0" />
    </joint>
    <link name="arm_1_link">
        <inertial>
            <mass value="0.06" />
            <origin rpy="0 0 0" xyz="0 0 0" />
            <inertia ixx="0.0" ixy="0.0" ixz="0.0" iyy="0.0" iyz="0.0" izz="0.0" />
        </inertial>
        <visual>
            <origin rpy="0 0 0" xyz="0 0 0" />
            <geometry>
                <box size="0.02 0.04 0.04" />
            </geometry>
            <material name="LightGrey" />
        </visual>
        <collision>
            <origin rpy="0 0 0" xyz="0 0 0" />
            <geometry>
                <box size="0.02 0.04 0.04" />
            </geometry>
        </collision>
    </link>

    <joint name="arm_1_joint" type="revolute">
        <origin xyz="0 0.01 0.0" rpy="0 0 0" />
        <axis xyz="0 0 1" />
        <parent link="arm_1_link" />
        <child link="arm_bracket_1" />
        <limit lower="-2.356" upper="2.356" effort="50" velocity="40" />
    </joint>

    <link name="arm_bracket_1">
        <inertial>
            <mass value="0.00658" />
            <origin xyz="0 0 0.03693" rpy="0 0 0" />
            <inertia ixx="0.00097149" ixy="0.0" ixz="0.0" iyy="0.00390446" iyz="0.0" izz="0.00346115" />
        </inertial>
        <visual>
            <origin xyz="0 0 0.029" rpy="0 0 0" />
            <geometry>
                <box size="0.052 0.025 0.002" />
            </geometry>
            <material name="Green" />
        </visual>
        <collision>
            <origin xyz="0 0 0.029" rpy="0 0 0" />
            <geometry>
                <box size="0.052 0.025 0.002" />
            </geometry>
        </collision>
    </link>

    <joint name="arm_2_joint" type="revolute">
        <origin xyz="0 0 0.052" rpy="0 0 0" />
        <axis xyz="1 0 0" />
        <parent link="arm_bracket_1" />
        <child link="arm_2_link" />
        <limit lower="-2.356" upper="2.356" effort="50" velocity="40" />
    </joint>
    <!-- arm_2_link = motor2 -->
    <link name="arm_2_link">
        <inertial>
            <mass value="0.0618" />
            <origin xyz="0.0005 -0.01505 0" rpy="0 0 0" />
            <inertia ixx="0.00703304" ixy="-0.00250174" ixz="0.0" iyy="0.00793603" iyz="0.0" izz="0.01230371" />
        </inertial>
        <visual>
            <origin xyz="0 -0.01 0" rpy="0 0 0" />
            <geometry>
                <box size="0.04 0.04 0.02" />
            </geometry>
            <material name="LightGrey" />
        </visual>
        <collision>
            <origin xyz="0 -0.01 0" rpy="0 0 0" />
            <geometry>
                <box size="0.04 0.04 0.02" />
            </geometry>
        </collision>
    </link>

    <!-- arm_bracket_2 = Asm_WeldedBracket -->
    <link name="arm_bracket_2">
        <inertial>
            <mass value="0.01175" />
            <origin xyz="0 -0.0029 0" rpy="0 0 0" />
            <inertia ixx="0.00229954" ixy="0.0" ixz="0.0" iyy="0.00519619" iyz="0.0" izz="0.00648306" />
        </inertial>
        <visual>
            <origin xyz="0 0 0" rpy="0 0 0" />
            <geometry>
                <box size="0.055 0.002 0.025" />
            </geometry>
            <material name="Green" />
        </visual>
        <collision>
            <origin xyz="0 0 0" rpy="0 0 0" />
            <geometry>
                <box size="0.055 0.002 0.025" />
            </geometry>
        </collision>
    </link>

    <joint name="arm_bracket_2_joint" type="fixed">
        <parent link="arm_2_link" />
        <child link="arm_bracket_2" />
        <origin xyz="0 -0.03653 0" rpy="0 0 0" />
    </joint>

    <joint name="arm_3_joint" type="revolute">
        <origin xyz="0 -0.06 0" rpy="0 0 0" />
        <axis xyz="1 0 0" />
        <parent link="arm_2_link" />
        <child link="arm_3_link" />
        <limit lower="-2.356" upper="2.356" effort="50" velocity="40" />
    </joint>
    <!-- arm_3_link = motor3 -->
    <link name="arm_3_link">
        <inertial>
            <mass value="0.0618" />
            <origin xyz="0.0005 -0.01505 0" rpy="0 0 0" />
            <inertia ixx="0.00703304" ixy="-0.00250174" ixz="0.0" iyy="0.00793603" iyz="0.0" izz="0.01230371" />
        </inertial>
        <visual>
            <origin xyz="0 -0.01 0" rpy="0 0 0" />
            <geometry>
                <box size="0.04 0.04 0.02" />
            </geometry>
            <material name="LightGrey" />
        </visual>
        <collision>
            <origin xyz="0 -0.01 0" rpy="0 0 0" />
            <geometry>
                <box size="0.04 0.04 0.02" />
            </geometry>
        </collision>
    </link>
    <!-- The entire grippper mass property is put on the first link -->
    <joint name="grip_joint_1" type="fixed">
        <parent link="arm_3_link" />
        <child link="grip_link_1" />
        <origin xyz="0 -0.0475 0.01" rpy="0 0 0" />
    </joint>
    <link name="grip_link_1">
        <inertial>
            <mass value="0.01023" />
            <origin xyz="0 -0.05355 0" rpy="0 0 0" />
            <inertia ixx="0.00443574" ixy="0.0" ixz="0.0" iyy="0.00287052" iyz="0.00000684" izz="0.00651523" />
        </inertial>
        <visual>
            <origin xyz="0 0 0" rpy="0 0 0" />
            <geometry>
                <box size="0.04 0.055 0.001" />
            </geometry>
            <material name="White" />
        </visual>
        <collision>
            <origin xyz="0 0 0" rpy="0 0 0" />
            <geometry>
                <box size="0.04 0.055 0.001" />
            </geometry>
        </collision>
    </link>
    <joint name="grip_joint_2" type="fixed">
        <parent link="arm_3_link" />
        <child link="grip_link_2" />
        <origin xyz="0 -0.0815 0.0033" rpy="0 0 0" />
    </joint>
    <link name="grip_link_2">
        <inertial>
            <mass value="0.005" />
            <origin xyz="0 0 0" rpy="0.785398 0 0" />
            <inertia ixx="0.0" ixy="0.0" ixz="0.0" iyy="0.0" iyz="0.0" izz="0.0" />
        </inertial>
        <visual>
            <origin xyz="0 0 0" rpy="0.785398 0 0" />
            <geometry>
                <box size="0.04 0.017 0.001" />
            </geometry>
            <material name="White" />
        </visual>
        <collision>
            <origin xyz="0 0 0" rpy="0.785398 0 0" />
            <geometry>
                <box size="0.04 0.017 0.001" />
            </geometry>
        </collision>
    </link>
    <joint name="grip_joint_3" type="fixed">
        <parent link="arm_3_link" />
        <child link="grip_link_3" />
        <origin xyz="0 -0.088 -0.0067" rpy="0 0 0" />
    </joint>
    <link name="grip_link_3">
        <inertial>
            <mass value="0.005" />
            <origin xyz="0 0 0" rpy="0 0 0" />
            <inertia ixx="0.0" ixy="0.0" ixz="0.0" iyy="0.0" iyz="0.0" izz="0.0" />
        </inertial>
        <visual>
            <origin xyz="0 0 0" rpy="0 0 0" />
            <geometry>
                <box size="0.04 0.001 0.007" />
            </geometry>
            <material name="White" />
        </visual>
        <collision>
            <origin xyz="0 0 0" rpy="0 0 0" />
            <geometry>
                <box size="0.04 0.001 0.007" />
            </geometry>
        </collision>
    </link>
</robot>